2024-07-12 14:39:26,738 INFO    StreamThr :27872 [internal.py:wandb_internal():85] W&B internal server running at pid: 27872, started at: 2024-07-12 14:39:26.733829
2024-07-12 14:39:26,743 DEBUG   HandlerThread:27872 [handler.py:handle_request():158] handle_request: status
2024-07-12 14:39:26,764 INFO    WriterThread:27872 [datastore.py:open_for_write():87] open: C:\Users\freeman\Desktop\ºòºê¶ó´õ\wandb\run-20240712_143926-jkmagx6u\run-jkmagx6u.wandb
2024-07-12 14:39:26,765 DEBUG   SenderThread:27872 [sender.py:send():379] send: header
2024-07-12 14:39:26,961 DEBUG   SenderThread:27872 [sender.py:send():379] send: run
2024-07-12 14:39:28,098 ERROR   SenderThread:27872 [internal_api.py:execute():349] 404 response executing GraphQL.
2024-07-12 14:39:28,098 ERROR   SenderThread:27872 [internal_api.py:execute():350] {"errors":[{"message":"entity my_entity not found during upsertBucket","path":["upsertBucket"]}],"data":{"upsertBucket":null}}
2024-07-12 14:39:28,106 ERROR   SenderThread:27872 [sender.py:send_run():1009] It appears that you do not have permission to access the requested resource. Please reach out to the project owner to grant you access. If you have the correct permissions, verify that there are no issues with your networking setup.(Error 404: Not Found)
Traceback (most recent call last):
  File "c:\Users\freeman\AppData\Local\Programs\Python\Python311\Lib\site-packages\wandb\sdk\lib\retry.py", line 131, in __call__
    result = self._call_fn(*args, **kwargs)
             ^^^^^^^^^^^^^^^^^^^^^^^^^^^^^^
  File "c:\Users\freeman\AppData\Local\Programs\Python\Python311\Lib\site-packages\wandb\sdk\internal\internal_api.py", line 345, in execute
    return self.client.execute(*args, **kwargs)  # type: ignore
           ^^^^^^^^^^^^^^^^^^^^^^^^^^^^^^^^^^^^
  File "c:\Users\freeman\AppData\Local\Programs\Python\Python311\Lib\site-packages\wandb\vendor\gql-0.2.0\wandb_gql\client.py", line 52, in execute
    result = self._get_result(document, *args, **kwargs)
             ^^^^^^^^^^^^^^^^^^^^^^^^^^^^^^^^^^^^^^^^^^^
  File "c:\Users\freeman\AppData\Local\Programs\Python\Python311\Lib\site-packages\wandb\vendor\gql-0.2.0\wandb_gql\client.py", line 60, in _get_result
    return self.transport.execute(document, *args, **kwargs)
           ^^^^^^^^^^^^^^^^^^^^^^^^^^^^^^^^^^^^^^^^^^^^^^^^^
  File "c:\Users\freeman\AppData\Local\Programs\Python\Python311\Lib\site-packages\wandb\sdk\lib\gql_request.py", line 59, in execute
    request.raise_for_status()
  File "c:\Users\freeman\AppData\Local\Programs\Python\Python311\Lib\site-packages\requests\models.py", line 1021, in raise_for_status
    raise HTTPError(http_error_msg, response=self)
requests.exceptions.HTTPError: 404 Client Error: Not Found for url: https://api.wandb.ai/graphql

During handling of the above exception, another exception occurred:

Traceback (most recent call last):
  File "c:\Users\freeman\AppData\Local\Programs\Python\Python311\Lib\site-packages\wandb\sdk\internal\sender.py", line 1007, in send_run
    server_run = self._init_run(run, config_value_dict)
                 ^^^^^^^^^^^^^^^^^^^^^^^^^^^^^^^^^^^^^^
  File "c:\Users\freeman\AppData\Local\Programs\Python\Python311\Lib\site-packages\wandb\sdk\internal\sender.py", line 1079, in _init_run
    server_run, inserted, server_messages = self._api.upsert_run(
                                            ^^^^^^^^^^^^^^^^^^^^^
  File "c:\Users\freeman\AppData\Local\Programs\Python\Python311\Lib\site-packages\wandb\apis\normalize.py", line 73, in wrapper
    raise err
  File "c:\Users\freeman\AppData\Local\Programs\Python\Python311\Lib\site-packages\wandb\apis\normalize.py", line 41, in wrapper
    return func(*args, **kwargs)
           ^^^^^^^^^^^^^^^^^^^^^
  File "c:\Users\freeman\AppData\Local\Programs\Python\Python311\Lib\site-packages\wandb\sdk\internal\internal_api.py", line 2224, in upsert_run
    response = self.gql(
               ^^^^^^^^^
  File "c:\Users\freeman\AppData\Local\Programs\Python\Python311\Lib\site-packages\wandb\sdk\internal\internal_api.py", line 317, in gql
    ret = self._retry_gql(
          ^^^^^^^^^^^^^^^^
  File "c:\Users\freeman\AppData\Local\Programs\Python\Python311\Lib\site-packages\wandb\sdk\lib\retry.py", line 147, in __call__
    retry_timedelta_triggered = check_retry_fn(e)
                                ^^^^^^^^^^^^^^^^^
  File "c:\Users\freeman\AppData\Local\Programs\Python\Python311\Lib\site-packages\wandb\util.py", line 968, in check_retry_fn
    return fallback_retry_fn(e)
           ^^^^^^^^^^^^^^^^^^^^
  File "c:\Users\freeman\AppData\Local\Programs\Python\Python311\Lib\site-packages\wandb\util.py", line 910, in no_retry_auth
    raise CommError(
wandb.errors.CommError: It appears that you do not have permission to access the requested resource. Please reach out to the project owner to grant you access. If you have the correct permissions, verify that there are no issues with your networking setup.(Error 404: Not Found)
2024-07-12 14:39:29,054 DEBUG   HandlerThread:27872 [handler.py:handle_request():158] handle_request: shutdown
2024-07-12 14:39:29,054 INFO    HandlerThread:27872 [handler.py:finish():882] shutting down handler
2024-07-12 14:39:29,154 INFO    SenderThread:27872 [sender.py:finish():1608] shutting down sender
2024-07-12 14:39:29,982 INFO    WriterThread:27872 [datastore.py:close():296] close: C:\Users\freeman\Desktop\ºòºê¶ó´õ\wandb\run-20240712_143926-jkmagx6u\run-jkmagx6u.wandb
